Workbook

Sheet Сводка
A1: Маркет-рисерч исполнителей: АО «Узавтосаноат», Ташкент
A2: Дата: 28.10.2026 · Период услуг по ТЗ: 01.11.2026–31.10.2027 (12 мес.) · КП действует 30 дней
A4: Лот | B4: Предмет | C4: Ключевые требования ТЗ | D4: Профильных компаний (●) | E4: Частично / субподряд (○) | F4: В шорт-листе
A5: AT13-1 | B5: AT13 Лот 1. Электроснабжение и ТП 0,4 кВ (пост 24/7) | C5: Допуск к электроустановкам до 1000 В, профобразование; пост 24/7 — 5 электриков (12/36); ТП №5676: 4×ТМГ-1000/10/0,4, 80 щитов | D5: =COUNTIF('Все компании'!D5:D53,"●") -> 1 | E5: =COUNTIF('Все компании'!D5:D53,"○") -> 5 | F5: =COUNTIF('AT13 шорт-лист'!$A:$A,A5) -> 5
A6: AT13-2 | B6: AT13 Лот 2. Холодоснабжение и вентиляция (4 чиллера, 18 AHU, 250 фанкойлов) | C6: Проф. (среднее спец./высшее) по холодильному оборудованию, руководитель — высшее; пост 24/7 в сезон охлаждения — 5 техников; 4 чиллера ZEPHYRUS по 1000 кВт, 18 AHU, 250 фанкойлов | D6: =COUNTIF('Все компании'!E5:E53,"●") -> 3 | E6: =COUNTIF('Все компании'!E5:E53,"○") -> 9 | F6: =COUNTIF('AT13 шорт-лист'!$A:$A,A6) -> 5
A7: AT13-3 | B7: AT13 Лот 3. Газ и котельная (3×Italheat 1,6 МВт, ГРП) | C7: Аттестация оператора котельной и допуск к газовому оборудованию; пост 24/7 в отопительный сезон — 5 операторов; блочно-модульная котельная 6,5 МВт (3×Italheat 1,6 МВт), ГРП; субподряд по лицензируемым работам — с согласия | D7: =COUNTIF('Все компании'!F5:F53,"●") -> 3 | E7: =COUNTIF('Все компании'!F5:F53,"○") -> 6 | F7: =COUNTIF('AT13 шорт-лист'!$A:$A,A7) -> 5
A8: AT13-4 | B8: AT13 Лот 4. Лифты (4 шт.) | C8: Разрешение на работы с лифтами (можно через лицензированного субподрядчика); 4 лифта; освобождение пассажиров ≤30 мин, авария 24/7 | D8: =COUNTIF('Все компании'!G5:G53,"●") -> 7 | E8: =COUNTIF('Все компании'!G5:G53,"○") -> 5 | F8: =COUNTIF('AT13 шорт-лист'!$A:$A,A8) -> 5
A9: AT13-5 | B9: AT13 Лот 5. Сантехника и тепловые пункты (пост 24/7) | C9: Профквалификация; пост 24/7 — 5 сантехников; 5 теплообменников 460 кВт, 15 насосов Magna, 40 насосов водоснабжения, пожарные насосные станции | D9: =COUNTIF('Все компании'!H5:H53,"●") -> 2 | E9: =COUNTIF('Все компании'!H5:H53,"○") -> 3 | F9: =COUNTIF('AT13 шорт-лист'!$A:$A,A9) -> 4
A10: AT13-6 | B10: AT13 Лот 6. Благоустройство: покрытия, газоны, фонтаны, плотник, фасад | C10: Без спец. образования; плотник — квалификация; высотники — допуск; 3 сотрудника 7 дней в неделю; покрытия 3 072,6 м², зелень 2 025,7 м², 2 фонтана, мойка фасада (субподряд) | D10: =COUNTIF('Все компании'!I5:I53,"●") -> 2 | E10: =COUNTIF('Все компании'!I5:I53,"○") -> 9 | F10: =COUNTIF('AT13 шорт-лист'!$A:$A,A10) -> 5
A11: MU30T-1 | B11: MU30 тех. Лот 1. Электроснабжение (дневной пост) | C11: Допуск до 1000 В; дневной пост 8 ч — 1 электрик; авария вне поста — прибытие ≤2 ч | D11: =COUNTIF('Все компании'!J5:J53,"●") -> 1 | E11: =COUNTIF('Все компании'!J5:J53,"○") -> 3 | F11: =COUNTIF('MU30 тех шорт-лист'!$A:$A,A11) -> 4
A12: MU30T-2 | B12: MU30 тех. Лот 2. Сантехника (дневной пост) | C12: Профквалификация; дневной пост 8 ч — 1 сантехник; авария — прибытие ≤2 ч | D12: =COUNTIF('Все компании'!K5:K53,"●") -> 1 | E12: =COUNTIF('Все компании'!K5:K53,"○") -> 3 | F12: =COUNTIF('MU30 тех шорт-лист'!$A:$A,A12) -> 4
A13: MU30T-3 | B13: MU30 тех. Лот 3. Лифт (1 шт.) | C13: Разрешение на работы с лифтами (субподряд допускается); 1 лифт; авария 24/7 | D13: =COUNTIF('Все компании'!L5:L53,"●") -> 7 | E13: =COUNTIF('Все компании'!L5:L53,"○") -> 5 | F13: =COUNTIF('MU30 тех шорт-лист'!$A:$A,A13) -> 5
A14: MU30T-4 | B14: MU30 тех. Лот 4. Территория и газоны | C14: Без спец. образования; 2 сотрудника 7 дней в неделю; покрытие 2 597,7 м², газоны и зелень 1 074,6 м² | D14: =COUNTIF('Все компании'!M5:M53,"●") -> 3 | E14: =COUNTIF('Все компании'!M5:M53,"○") -> 3 | F14: =COUNTIF('MU30 тех шорт-лист'!$A:$A,A14) -> 4
A15: MU30K | B15: MU30 клининг. Уборка МОП 2 305,19 м² | C15: 4 уборщика (8:00–17:00 и 9:00–18:00), генуборка раз в квартал (суббота, бригада ≥6), высотники с допуском | D15: =COUNTIF('Все компании'!N5:N53,"●") -> 8 | E15: =COUNTIF('Все компании'!N5:N53,"○") -> 2 | F15: =COUNTIF('MU30 клининг шорт-лист'!$A:$A,A15) -> 7
A16: Всего компаний в списке | D16: =COUNTA('Все компании'!B5:B53) -> 49
A18: Главное
A19: 1. Интегрированного FM-оператора, который закрыл бы все 6 лотов AT13 своими силами, в открытых источниках не найдено. Реалистичная схема — генподрядчик (многопрофильная компания) + субподрядчики по лифтам, котельной/ГРП и мойке фасада (ТЗ п. 6.7 это допускает), либо запрос КП по лотам.
A20: 2. Лифты: самый насыщенный и регулируемый сегмент. Марка и грузоподъёмность лифтов в ТЗ не указаны («по техпаспорту») — их нужно сообщить исполнителям: от марки зависит, кто приоритетен (KONE → Lift Universal, Otis → LIFTEES). Наличие разрешения сверять по реестру КПРЯБ на gov.uz/cirns.
A21: 3. Котельная: котлы Italheat — логично запросить КП у ITALHEAT GROUP (поставщик бренда). Узких подрядчиков по эксплуатации промышленных котельных и ГРП в открытом доступе мало — проверить аттестацию операторов и допуски по газу.
A22: 4. Чиллеры ZEPHYRUS: марка в узбекских источниках не встречается. У кандидатов запросить опыт обслуживания чиллеров ≥1 МВт с воздушным охлаждением.
A23: 5. Электрика с ТП 10/0,4 кВ и постом 24/7 — самый слабый по предложению сегмент: компании в основном монтажники или электролаборатории. Возможна связка: исполнитель поста + электролаборатория (PROF-LEND) для испытаний.
A24: 6. Клининг и озеленение — конкурентный рынок, 3+ КП собрать реально. NewCleaner может закрыть клининг MU30 и территорию MU30 одним договором.
A25: 7. Обязательный осмотр объекта до подачи КП (ТЗ п. 6.8.2): в запросе нужно указать дату и время осмотра.
A26: Ограничения
A27: • При сборе данных не было прямого доступа к goldenpages.uz, orginfo.uz, xarid.uzex.uz, etender.uzex.uz, 2gis.uz, olx.uz, top.uz, gov.uz, license.gov.uz. Данные собраны через веб-поиск (фрагменты сайтов компаний и каталогов). Перед рассылкой проверить номер звонком.
A28: • Победителей аналогичных госзакупок, ИНН и директоров установить не удалось (реестры и порталы недоступны) — колонка «Опыт в госзакупках» не заполнена.
A29: • Телефон +998 78 140-09-09 с адресом «пр. Мирзо Улугбека, 30» показывается в Golden Pages у многих несвязанных компаний — исключён как служебный номер каталога.

Sheet Все компании
A1: Потенциальные исполнители — общий список (Ташкент), данные на 28.10.2026
A2: ● — профиль совпадает с лотом; ○ — частично / как субподрядчик. Достоверность: A — контакты с официального сайта; B — каталог или один источник; C — неполные/старые данные, требуется проверка.
A4: № | B4: Компания | C4: Категория | D4: AT13-1 | E4: AT13-2 | F4: AT13-3 | G4: AT13-4 | H4: AT13-5 | I4: AT13-6 | J4: MU30T-1 | K4: MU30T-2 | L4: MU30T-3 | M4: MU30T-4 | N4: MU30K | O4: Специализация / подтверждение | P4: Лицензия / разрешение | Q4: Телефон(ы) | R4: E-mail | S4: Сайт | T4: Telegram / соцсети | U4: Адрес | V4: Источник | W4: Достоверность | X4: Примечание | Y4: Опыт в госзакупках
A5: 1 | B5: Lift Universal (ООО «LIFT-UNIVERSAL») | C5: Лифты | G5: ● | L5: ● | O5: Официальный и единственный партнёр KONE в Узбекистане: монтаж, ремонт, ТО лифтов и эскалаторов | P5: Лицензию проверить (в видимой части реестра КПРЯБ не найдено) | Q5: +998 71 205 52 25; +998 71 254 86 06 | R5: info@lift-universal.uz | S5: lift-universal.uz | T5: t.me/LiftUniversalKONE; Instagram @lift.universal | U5: Ташкент, Мирзо-Улугбекский р-н, ул. Буюк Ипак Йули, 49 (на стр. «Контакты» — Яккасарайский р-н, ул. Кушбеги, 10Б) | V5: https://lift-universal.uz/kontakty | W5: A | X5: Приоритет, если лифты KONE. Адрес на сайте указан двояко | Y5: не проверено (порталы закупок недоступны)
A6: 2 | B6: VALT LIFT (ООО «VALT-LIFT») | C6: Лифты | G6: ● | L6: ● | O6: Проектирование, производство, монтаж и обслуживание лифтов; без выходных 9:00–20:00 | P6: В реестре разрешений КПРЯБ на монтаж и ремонт лифтов (по выдержке gov.uz/cirns) | Q6: +998 71 235 20 05 | R6: info@valtlift.com | S6: valtlift.com | T6: — | U6: Ташкент, Юнусабадский р-н, Ц-5, 54/42 | V6: https://valtlift.com/kontakty | W6: A | Y6: не проверено (порталы закупок недоступны)
A7: 3 | B7: LIFTEES (Expert Elevator System) | C7: Лифты | G7: ● | L7: ● | O7: Официальный дистрибьютор Otis в Узбекистане; поставка, монтаж, ремонт, ТО | P7: В реестре КПРЯБ есть «EXPERT ELEVATOR GROUP» — связь проверить | Q7: +998 71 207 40 04 | R7: info@liftees.uz; tahir.salihov@mail.ru (Expert Elevator Service) | S7: liftees.uz | T7: — | U7: Ташкент, ул. Богибустон, 184 (Expert Elevator Service ООО: Шайхантахурский р-н, ул. Бунёдкор, 6А) | V7: https://www.otis.com/zh/cn/distributors ; https://top.uz/company/expert-elevator-service-ooo | W7: A | X7: Приоритет, если лифты Otis | Y7: не проверено (порталы закупок недоступны)
A8: 4 | B8: Master-Lift (ООО «MASTER-LIFT») | C8: Лифты | G8: ● | L8: ● | O8: ТО лифтового оборудования; также ИБП и дизель-генераторы | P8: В реестре разрешений КПРЯБ (по выдержке gov.uz/cirns) | Q8: +998 94 660 41 52; +998 95 169 74 63; +998 95 143 74 63 | R8: masterlift@list.ru | S8: — | T8: — | U8: Ташкент, Юнусабадский р-н, ул. Ифтихор, 29 (top.uz: пр. Шарафа Рашидова, 16) | V8: https://gigal.uz/objects/dir/tashkent/oborudovanie_i_tehnika/1188-lifti/ ; top.uz | W8: B | Y8: не проверено (порталы закупок недоступны)
A9: 5 | B9: High Lift Solution | C9: Лифты | G9: ● | L9: ● | O9: Продажа, монтаж и обслуживание лифтов, подъёмников, эскалаторов | P9: В реестре разрешений КПРЯБ («HIGH LIFT SOLUTION», по выдержке) | Q9: +998 33 038 88 88 | R9: — | S9: high-lift.uz | T9: — | U9: Ташкент | V9: https://high-lift.uz/ | W9: B | Y9: не проверено (порталы закупок недоступны)
A10: 6 | B10: Beta Lift Asia Uzbekistan | C10: Лифты | G10: ● | L10: ● | O10: Лифтовое оборудование, монтаж и сервис | P10: В реестре разрешений КПРЯБ («BETA LIFT ASIA», по выдержке) | Q10: +998 90 043 40 30; +998 90 047 40 30; +998 78 147 40 30 | R10: — | S10: — | T10: Instagram @beta_lift_asia_uzbekistan | U10: Ташкент, Мирзо-Улугбекский р-н, массив Ялангач, ул. Зафар Диёр, 119а | V10: https://www.instagram.com/beta_lift_asia_uzbekistan/ ; fastbase.com | W10: B | Y10: не проверено (порталы закупок недоступны)
A11: 7 | B11: YUMA LIFT (ООО «YUMA GREEN») | C11: Лифты | G11: ● | L11: ● | O11: Производство, поставка и обслуживание пассажирских, больничных и грузовых лифтов | P11: Проверить по реестру КПРЯБ | Q11: +998 95 478 88 87; +998 71 280 60 60 | R11: yumaliftuzbekistan@gmail.com | S11: yumalift.uz | T11: — | U11: Ташкент, Яккасарайский р-н, ул. Шота Руставели, 53Б (ориентир: базар «Аския») | V11: https://www.yellowpages.uz/kompaniya/yuma-lift ; top.uz | W11: B | Y11: не проверено (порталы закупок недоступны)
A12: 8 | B12: Alpha Partners Group | C12: Лифты | G12: ○ | L12: ○ | O12: Продажа и монтаж лифтов; сервис уточнить | P12: Проверить по реестру КПРЯБ | Q12: +998 97 741 77 73; +998 97 758 77 73 | R12: — | S12: apg.uz | T12: — | U12: Ташкент | V12: http://www.apg.uz/ ; gigal.uz | W12: B | Y12: не проверено (порталы закупок недоступны)
A13: 9 | B13: Trust Lift | C13: Лифты | G13: ○ | L13: ○ | O13: Обслуживание лифтов (по каталогу) | P13: В реестре КПРЯБ есть «TRUST QUALITY ELEVATORS» — возможно, та же компания | Q13: +998 98 303 08 01; +998 93 534 36 06; +998 93 507 52 65 | R13: — | S13: — | T13: — | U13: Ташкент, Мирзо-Улугбекский р-н, ул. Шуртепа, 159 | V13: gigal.uz | W13: C | Y13: не проверено (порталы закупок недоступны)
A14: 10 | B14: Lift Montaj Servis (ООО «LIFT MONTAJ SERVIS») | C14: Лифты | G14: ○ | L14: ○ | O14: Монтаж и сервис лифтов (по каталогу) | P14: Проверить по реестру КПРЯБ | Q14: +998 90 329 91 38; +998 90 999 12 07; +998 71 246 72 62 | R14: — | S14: — | T14: — | U14: Ташкент | V14: gigal.uz ; goldenpages.uz (Id=68776) | W14: C | Y14: не проверено (порталы закупок недоступны)
A15: 11 | B15: Ideal Lift Servis (ООО) | C15: Лифты | G15: ○ | L15: ○ | O15: Монтаж, ремонт и обслуживание лифтов | P15: Проверить по реестру КПРЯБ | Q15: +998 91 441 04 10; +998 33 001 04 10 | R15: — | S15: — | T15: — | U15: Ташкент | V15: https://stroyka.uz/offer/montazh-remont-i-obsluzhivanie-liftov ; top.uz | W15: C | Y15: не проверено (порталы закупок недоступны)
A16: 12 | B16: Safety Elevators & Escalators (дистрибьютор Schindler) | C16: Лифты | G16: ○ | L16: ○ | O16: Дистрибьютор Schindler (данные старые): ремонт, запчасти | P16: Проверить | Q16: +998 90 328 82 28; +998 71 207 00 50 (top.uz, «Schindler эксклюзивный дистрибьютор») | R16: seeuzbekistan@gmail.com | S16: see.uz | T16: — | U16: Ташкент, Яшнабадский р-н, ул. Боку, 179А, 100076 | V16: https://group.schindler.com/en/system/worldwide.html ; yellowpages.uz | W16: C | X16: Только если лифты Schindler; запись в каталоге Schindler старая | Y16: не проверено (порталы закупок недоступны)
A17: 13 | B17: ITALHEAT GROUP (СП ООО) | C17: Котельная / отопление | F17: ● | H17: ○ | O17: Импортёр и дистрибьютор котельного, климатического и вентиляционного оборудования (котлы Italheat установлены на объекте); официальный дилер и сервисный центр Immergas | P17: Допуски по промбезопасности и газу уточнить; ГРП — через субподряд | Q17: +998 71 231 64 99; +998 71 231 64 90 | R17: info@italheat.com | S17: italheat.com | T17: — | U17: Ташкент, Мирабадский р-н, массив Госпитальный, 7 (по каталогам есть и другие адреса) | V17: https://italheat.com/about-us/ ; yellowpages.uz | W17: B | X17: Приоритет: оборудование их марки. Уточнить, берут ли эксплуатацию с операторами 24/7 или только сервис | Y17: не проверено (порталы закупок недоступны)
A18: 14 | B18: FUSE HVAC Engineering | C18: ОВиК / котельные | E18: ● | F18: ● | H18: ○ | O18: Обслуживание чиллеров и фанкойлов, VRF, регламент вентиляции, пусконаладка; ТО котельных, промывка систем отопления, подготовка к сезону | P18: Допуски по газу проверить | Q18: +998 90 998 00 50 (также Telegram) | R18: info@fuse.uz | S18: fuse.uz | T18: — | U18: Ташкент, ул. Яхьё Гулямова, 38, 100060 | V18: https://fuse.uz/en/about-us/ ; https://fuse.uz/en/konditsionirovanie/obsluzhivanie-chiller/ | W18: A | X18: Кандидат на несколько лотов AT13 (2, 3, 5) | Y18: не проверено (порталы закупок недоступны)
A19: 15 | B19: Smart Heating Systems | C19: ОВиК / теплоснабжение | E19: ○ | F19: ● | H19: ● | K19: ○ | O19: Инжиниринг отопления, вентиляции, охлаждения; теплообменники, насосы, котлы; гарантийный и сервисный ремонт; 15+ лет | P19: Допуски по газу проверить | Q19: +998 71 248 79 79; +998 90 926 67 76; +998 97 480 79 80 | R19: info@smartheating.uz | S19: smartheating.uz | T19: — | U19: Ташкент, ул. Ифтихор, 9/1, 100057 (на сайте также ул. Туркурган, 2/4) | V19: https://smartheating.uz/kontakty | W19: A | X19: Профиль: ИТП/ТП (пластинчатые теплообменники, насосы Magna) | Y19: не проверено (порталы закупок недоступны)
A20: 16 | B20: Gas Service | C20: Газовое оборудование | F20: ○ | O20: Эксплуатация ГРП и ГРПШ с РДУК-150 | P20: Лицензию проверить | Q20: — | R20: — | S20: — | T20: — | U20: Ташкент | V20: https://stroyka.uz/offer/ekspluataciya-grp-i-grps-s-rduk-150 | W20: C | X20: Кандидат на субподряд по ГРП; контакты — на странице объявления | Y20: не проверено (порталы закупок недоступны)
A21: 17 | B21: BTS Group | C21: Газовое оборудование | F21: ○ | O21: Промышленные газовые и двухтопливные горелки: монтаж, пусконаладка, сервис | P21: Проверить | Q21: — | R21: — | S21: btsgroup.uz | T21: — | U21: Ташкент | V21: https://www.btsgroup.uz/ | W21: C | X21: Субподряд по горелкам | Y21: не проверено (порталы закупок недоступны)
A22: 18 | B22: Uztexenergo (ООО) | C22: Котельная / отопление | F22: ○ | O22: Сервисный центр по ремонту котлов и ТО; монтаж промышленных котлов | P22: Проверить | Q22: — | R22: — | S22: — | T22: — | U22: Ташкент | V22: https://stroyka.uz/offer/servisnyi-centr-po-remontu-kotlov-v-taskente-i-to-lyuboi-sloznosti | W22: C | Y22: не проверено (порталы закупок недоступны)
A23: 19 | B23: Adrian Eco | C23: Котельная / отопление | F23: ○ | O23: Монтаж и пусконаладка промышленных котлов 500 кВт – 100 МВт | P23: Проверить | Q23: — | R23: — | S23: — | T23: — | U23: Ташкент | V23: https://www.prom.uz/tags/ustanovka-kotlov/ | W23: C | Y23: не проверено (порталы закупок недоступны)
A24: 20 | B24: Climate Master | C24: ОВиК / котлы | E24: ○ | F24: ○ | O24: Ремонт и ТО чиллеров, кондиционеров, котлов; круглосуточно | P24: Проверить | Q24: +998 33 566 67 68 | R24: info@climate-master.uz | S24: climate-master.uz | T24: — | U24: Ташкент, Чиланзарский р-н, дом 87 | V24: https://climate-master.uz/ | W24: B | X24: Скорее сервисная мастерская, масштаб проверить | Y24: не проверено (порталы закупок недоступны)
A25: 21 | B25: Everest Group (ООО «EVEREST GROUP») | C25: ОВиК | E25: ● | O25: Промышленная вентиляция и кондиционирование: поставка чиллеров и фанкойлов, VRF, монтаж, пусконаладка; объекты: головной офис Orient Finance Bank, Holiday Inn, BEFIT BOX | P25: — | Q25: +998 55 500 99 00; +998 99 119 12 12 | R25: info@everestgroup.uz | S25: everestgroup.uz | T25: — | U25: Ташкент, Яшнабадский р-н, ул. Уйсозлар, 75 (ориентир: 1-й автобусный парк) | V25: https://everestgroup.uz/contacts/ | W25: A | Y25: не проверено (порталы закупок недоступны)
A26: 22 | B26: DC Engineering / Direct Cool (Daikin) | C26: ОВиК | E26: ● | O26: Официальный дистрибьютор и авторизованный сервисный центр Daikin в Узбекистане; с 2005 г.; 213 объектов, 34 специалиста (по данным компании) | P26: — | Q26: +998 77 299 07 77 (сервисный центр) | R26: — | S26: daikin-dc.uz; directcool.uz | T26: Facebook daikinuz | U26: Ташкент, Алмазарский р-н, ул. Янги Олмазор, 7а/36 | V26: https://daikin-dc.uz/ ; https://daikin-dc.uz/about/ | W26: B | Y26: не проверено (порталы закупок недоступны)
A27: 23 | B27: Climate Expert | C27: ОВиК | E27: ○ | O27: Заявляет статус официального дистрибьютора Daikin; поставка, монтаж, сервис | P27: — | Q27: +998 78 888 00 08 | R27: — | S27: climate-expert.uz | T27: — | U27: Ташкент, Юнусабадский р-н | V27: https://climate-expert.uz/site/contact | W27: B | Y27: не проверено (порталы закупок недоступны)
A28: 24 | B28: Climate Center | C28: ОВиК / котлы | E28: ○ | F28: ○ | O28: Ремонт чиллеров Daikin, Trane, Carrier и др.; бизнес-центры, заводы, медучреждения; также газовые котлы | P28: — | Q28: +998 90 849 22 22 (также Telegram) | R28: — | S28: climatecenter.uz | T28: — | U28: Ташкент, Сергелийский р-н, Чаштепа, 336 | V28: https://climatecenter.uz/ | W28: B | Y28: не проверено (порталы закупок недоступны)
A29: 25 | B29: Climat-Montaj (Климат Монтаж) | C29: ОВиК | E29: ○ | O29: Производство воздуховодов, монтаж чиллеров, ремонт чиллеров и фанкойлов | P29: — | Q29: +998 71 502 01 32 | R29: info@climat-montaj.uz; climat-montaj@mail.ru | S29: climat-montaj.uz | T29: — | U29: Ташкентская обл., Янгиюльский р-н, пос. Чаманзор | V29: https://climat-montaj.uz/ | W29: B | X29: Офис за пределами Ташкента | Y29: не проверено (порталы закупок недоступны)
A30: 26 | B30: Mazza Project | C30: ОВиК | E30: ○ | O30: Проектирование, монтаж, пусконаладка и обслуживание вентиляции, кондиционирования, дымоудаления, холодоснабжения; 15 лет | P30: — | Q30: — | R30: — | S30: mazzaproject.uz | T30: — | U30: Ташкент | V30: https://mazzaproject.uz/ | W30: C | X30: Контакты на сайте (в поиске не отображались) | Y30: не проверено (порталы закупок недоступны)
A31: 27 | B31: Ventsystems | C31: ОВиК | E31: ○ | O31: Поставка чиллеров, монтаж и пусконаладка под ключ | P31: — | Q31: — | R31: — | S31: ventsystems.uz | T31: — | U31: Ташкент | V31: https://ventsystems.uz/chilleri | W31: C | Y31: не проверено (порталы закупок недоступны)
A32: 28 | B32: PROF-LEND (ООО) | C32: Электрика / ТП | D32: ○ | J32: ○ | O32: Электротехническая лаборатория: испытания электроустановок до 220 кВ, замеры сопротивления изоляции, ремонт и обслуживание трансформаторов | P32: Регистрация электролаборатории — проверить | Q32: +998 90 187 14 67 | R32: admin@proflend.uz | S32: proflend.uz | T32: — | U32: Ташкент | V32: https://www.proflend.uz/ | W32: A | X32: Профиль: ТП и испытания; на пост 24/7 — уточнить, могут ли дать персонал | Y32: не проверено (порталы закупок недоступны)
A33: 29 | B33: SVET.UZ (OMEGA ENGINEERING GROUP) | C33: Электрика / ТП | D33: ○ | J33: ○ | O33: Электромонтаж, монтаж ТП/РП/КТП/БКТП, сборка электрощитов, опоры освещения; свои бригады | P33: — | Q33: +998 99 855 18 55; +998 99 825 82 56 | R33: — | S33: svet.uz | T33: — | U33: Ташкент, Яккасарайский р-н, ул. Ш. Руставели, 150, 100121 (в каталогах есть и другие адреса) | V33: https://svet.uz/uslugi/montazh-tp-rp-rtp-ktp-bktp/ ; goldenpages.uz | W33: B | X33: Монтажник: уточнить готовность к эксплуатации и посту 24/7 | Y33: не проверено (порталы закупок недоступны)
A34: 30 | B34: Electrogrand Group (ООО) | C34: Электрика / ТП | D34: ○ | O34: Изготовление, монтаж и пусконаладка КТП под ключ | P34: — | Q34: +998 98 309 69 00 | R34: — | S34: — | T34: — | U34: Ташкент | V34: https://uz.bizorg.su/tashkent-rg/transformatornye-podstantsii-r | W34: C | Y34: не проверено (порталы закупок недоступны)
A35: 31 | B35: ELEKTROMOTORS.UZ (Infinitely Hi-Tech Electro Motors) | C35: Электрика / ТП | D35: ○ | O35: Монтаж, ремонт и наладка электрооборудования, перемотка двигателей; ремонт ТП КТП/КТПН (по сайту) | P35: — | Q35: +998 94 680 15 04 | R35: — | S35: elektromotors.uz | T35: — | U35: Ташкентская обл., Кибрай, ул. Бабура, 7/1 | V35: goldenpages.uz ; elektromotors.uz | W35: C | X35: Офис в области | Y35: не проверено (порталы закупок недоступны)
A36: 32 | B36: Reshenie.uz | C36: Тех. эксплуатация зданий (FM) | D36: ● | E36: ○ | H36: ● | J36: ● | K36: ● | O36: Комплексное обслуживание зданий: электро-, тепло-, водоснабжение, канализация, вентиляция; ведение журналов и актов, контроль подрядчиков; также пожарная безопасность, СКУД, IT | P36: — | Q36: +998 93 103 70 77 (Telegram/WhatsApp) | R36: reshenie.uz@mail.ru (на англ. версии — ssaash@mail.ru) | S36: reshenie.uz | T36: — | U36: Ташкент, ул. Алишера Навои, 16А, офис 501 | V36: https://reshenie.uz/ru/uslugi/obsluzhivanie-zdanij/ ; https://reshenie.uz/en/contacts/ | W36: B | X36: Один из немногих, кто прямо заявляет техэксплуатацию зданий. Юрлицо и масштаб проверить | Y36: не проверено (порталы закупок недоступны)
A37: 33 | B37: Eco-Service (service-eco.uz) | C37: Многопрофильный сервис | D37: ○ | E37: ○ | I37: ○ | J37: ○ | K37: ○ | N37: ● | O37: Клининг для юрлиц (договор, НДС 12%, супервайзер на объект), мойка фасадов альпинистами (допуски EN 365), электрики, ремонт чиллеров и котлов | P37: — | Q37: +998 78 555 48 94; +998 88 113 87 87 | R37: — | S37: service-eco.uz | T37: — | U37: Ташкент, Алмазар, массив 8/1 | V37: https://service-eco.uz/business/ ; https://service-eco.uz/cleaning/pomeshhenij/dlya-yur-licz/ | W37: B | X37: Ориентир по цене (сайт): от 4 000 сум/м² за ежедневную поддерживающую уборку | Y37: не проверено (порталы закупок недоступны)
A38: 34 | B38: EUROSANT | C38: Сантехника | H38: ○ | K38: ○ | O38: Абонентское сантехническое обслуживание по договору (аутсорсинг) для организаций: отопление, водоснабжение, канализация | P38: — | Q38: — | R38: — | S38: eurosant.uz | T38: — | U38: Ташкент | V38: https://eurosant.uz/ | W38: C | X38: Контакты на сайте (в поиске не отображались) | Y38: не проверено (порталы закупок недоступны)
A39: 35 | B39: Profuborka (Asia Cleaning Service) | C39: Клининг | N39: ● | O39: Клининг для юрлиц, комплексная ежедневная уборка офисов; ~16 лет на рынке, ~100 сотрудников (по данным сайта) | P39: — | Q39: +998 71 200 03 28; +998 97 402 28 20; +998 97 037 28 20 | R39: asiaclean@mail.ru | S39: profuborka.uz | T39: Facebook profuborka.uz | U39: Ташкент, ул. Бунёдкор, 42/1 | V39: https://profuborka.uz/ | W39: A | Y39: не проверено (порталы закупок недоступны)
A40: 36 | B40: NewCleaner | C40: Клининг / территория | I40: ○ | M40: ● | N40: ● | O40: Уборка офисов и коммерческих помещений; уборка, благоустройство и уход за территориями; ландшафтное озеленение коммерческих объектов | P40: — | Q40: +998 94 431 62 22; +998 33 100 22 00 | R40: info@newcleaner.uz | S40: newcleaner.uz | T40: Telegram @newcleaneruz | U40: Ташкент, Мирзо-Улугбекский р-н, ул. Феруза, 13/86 | V40: https://newcleaner.uz/contact/ | W40: A | X40: Может закрыть клининг MU30 и лот 4 MU30 одним подрядчиком | Y40: не проверено (порталы закупок недоступны)
A41: 37 | B41: Uborka24 | C41: Клининг | I41: ○ | N41: ● | O41: Коммерческий клининг: офисы, общие зоны бизнес-центров, ТЦ; мойка фасадов альпинистами | P41: — | Q41: +998 94 880 95 45 (заказ); +998 33 979 67 68 (жалобы) | R41: info@uborka24.uz | S41: uborka24.uz | T41: — | U41: Ташкент, ул. Чилонзор, 87, 100070 (на сайте указаны и другие адреса) | V41: https://uborka24.uz/kontakty | W41: A | Y41: не проверено (порталы закупок недоступны)
...

Sheet AT13 шорт-лист
A1: AT13 шорт-лист: приоритетные компании для запроса КП
A2: Контакты подтягиваются формулами из листа «Все компании». Жёлтые колонки — для отметок закупщика (статус — из списка).
A4: Лот | B4: Приоритет | C4: Компания | D4: Почему в списке | E4: Телефон(ы) | F4: E-mail | G4: Сайт | H4: Достоверность | I4: Статус | J4: Дата запроса | K4: Комментарий
A5: AT13 Лот 1. Электроснабжение и ТП 0,4 кВ (пост 24/7)
A6: AT13-1 | B6: 1 | C6: Reshenie.uz | D6: Заявляет техэксплуатацию зданий целиком (электро/тепло/вода), ведение журналов | E6: =IFERROR(INDEX('Все компании'!$Q$5:$Q$53,MATCH(C6,'Все компании'!$B$5:$B$53,0)),"") -> +998 93 103 70 77 (Telegram/WhatsApp) | F6: =IFERROR(INDEX('Все компании'!$R$5:$R$53,MATCH(C6,'Все компании'!$B$5:$B$53,0)),"") -> reshenie.uz@mail.ru (на англ. версии — ssaash@mail.ru) | G6: =IFERROR(INDEX('Все компании'!$S$5:$S$53,MATCH(C6,'Все компании'!$B$5:$B$53,0)),"") -> reshenie.uz | H6: =IFERROR(INDEX('Все компании'!$W$5:$W$53,MATCH(C6,'Все компании'!$B$5:$B$53,0)),"") -> B | I6: Не связывались
A7: AT13-1 | B7: 2 | C7: SVET.UZ (OMEGA ENGINEERING GROUP) | D7: Монтаж ТП/КТП и щитов, свои бригады | E7: =IFERROR(INDEX('Все компании'!$Q$5:$Q$53,MATCH(C7,'Все компании'!$B$5:$B$53,0)),"") -> +998 99 855 18 55; +998 99 825 82 56 | F7: =IFERROR(INDEX('Все компании'!$R$5:$R$53,MATCH(C7,'Все компании'!$B$5:$B$53,0)),"") -> — | G7: =IFERROR(INDEX('Все компании'!$S$5:$S$53,MATCH(C7,'Все компании'!$B$5:$B$53,0)),"") -> svet.uz | H7: =IFERROR(INDEX('Все компании'!$W$5:$W$53,MATCH(C7,'Все компании'!$B$5:$B$53,0)),"") -> B | I7: Не связывались
A8: AT13-1 | B8: 3 | C8: PROF-LEND (ООО) | D8: Электролаборатория, обслуживание трансформаторов — для ТП и замеров | E8: =IFERROR(INDEX('Все компании'!$Q$5:$Q$53,MATCH(C8,'Все компании'!$B$5:$B$53,0)),"") -> +998 90 187 14 67 | F8: =IFERROR(INDEX('Все компании'!$R$5:$R$53,MATCH(C8,'Все компании'!$B$5:$B$53,0)),"") -> admin@proflend.uz | G8: =IFERROR(INDEX('Все компании'!$S$5:$S$53,MATCH(C8,'Все компании'!$B$5:$B$53,0)),"") -> proflend.uz | H8: =IFERROR(INDEX('Все компании'!$W$5:$W$53,MATCH(C8,'Все компании'!$B$5:$B$53,0)),"") -> A | I8: Не связывались
A9: AT13-1 | B9: 4 | C9: Electrogrand Group (ООО) | D9: КТП под ключ, пусконаладка | E9: =IFERROR(INDEX('Все компании'!$Q$5:$Q$53,MATCH(C9,'Все компании'!$B$5:$B$53,0)),"") -> +998 98 309 69 00 | F9: =IFERROR(INDEX('Все компании'!$R$5:$R$53,MATCH(C9,'Все компании'!$B$5:$B$53,0)),"") -> — | G9: =IFERROR(INDEX('Все компании'!$S$5:$S$53,MATCH(C9,'Все компании'!$B$5:$B$53,0)),"") -> — | H9: =IFERROR(INDEX('Все компании'!$W$5:$W$53,MATCH(C9,'Все компании'!$B$5:$B$53,0)),"") -> C | I9: Не связывались
A10: AT13-1 | B10: 5 | C10: Eco-Service (service-eco.uz) | D10: Электрики, работа с юрлицами | E10: =IFERROR(INDEX('Все компании'!$Q$5:$Q$53,MATCH(C10,'Все компании'!$B$5:$B$53,0)),"") -> +998 78 555 48 94; +998 88 113 87 87 | F10: =IFERROR(INDEX('Все компании'!$R$5:$R$53,MATCH(C10,'Все компании'!$B$5:$B$53,0)),"") -> — | G10: =IFERROR(INDEX('Все компании'!$S$5:$S$53,MATCH(C10,'Все компании'!$B$5:$B$53,0)),"") -> service-eco.uz | H10: =IFERROR(INDEX('Все компании'!$W$5:$W$53,MATCH(C10,'Все компании'!$B$5:$B$53,0)),"") -> B | I10: Не связывались
A11: AT13 Лот 2. Холодоснабжение и вентиляция (4 чиллера, 18 AHU, 250 фанкойлов)
A12: AT13-2 | B12: 1 | C12: FUSE HVAC Engineering | D12: Сервис чиллеров, фанкойлов, регламент вентиляции | E12: =IFERROR(INDEX('Все компании'!$Q$5:$Q$53,MATCH(C12,'Все компании'!$B$5:$B$53,0)),"") -> +998 90 998 00 50 (также Telegram) | F12: =IFERROR(INDEX('Все компании'!$R$5:$R$53,MATCH(C12,'Все компании'!$B$5:$B$53,0)),"") -> info@fuse.uz | G12: =IFERROR(INDEX('Все компании'!$S$5:$S$53,MATCH(C12,'Все компании'!$B$5:$B$53,0)),"") -> fuse.uz | H12: =IFERROR(INDEX('Все компании'!$W$5:$W$53,MATCH(C12,'Все компании'!$B$5:$B$53,0)),"") -> A | I12: Не связывались
A13: AT13-2 | B13: 2 | C13: Everest Group (ООО «EVEREST GROUP») | D13: Чиллеры и фанкойлы, банковские офисы и гостиницы | E13: =IFERROR(INDEX('Все компании'!$Q$5:$Q$53,MATCH(C13,'Все компании'!$B$5:$B$53,0)),"") -> +998 55 500 99 00; +998 99 119 12 12 | F13: =IFERROR(INDEX('Все компании'!$R$5:$R$53,MATCH(C13,'Все компании'!$B$5:$B$53,0)),"") -> info@everestgroup.uz | G13: =IFERROR(INDEX('Все компании'!$S$5:$S$53,MATCH(C13,'Все компании'!$B$5:$B$53,0)),"") -> everestgroup.uz | H13: =IFERROR(INDEX('Все компании'!$W$5:$W$53,MATCH(C13,'Все компании'!$B$5:$B$53,0)),"") -> A | I13: Не связывались
A14: AT13-2 | B14: 3 | C14: DC Engineering / Direct Cool (Daikin) | D14: Авторизованный сервис Daikin, 34 специалиста | E14: =IFERROR(INDEX('Все компании'!$Q$5:$Q$53,MATCH(C14,'Все компании'!$B$5:$B$53,0)),"") -> +998 77 299 07 77 (сервисный центр) | F14: =IFERROR(INDEX('Все компании'!$R$5:$R$53,MATCH(C14,'Все компании'!$B$5:$B$53,0)),"") -> — | G14: =IFERROR(INDEX('Все компании'!$S$5:$S$53,MATCH(C14,'Все компании'!$B$5:$B$53,0)),"") -> daikin-dc.uz; directcool.uz | H14: =IFERROR(INDEX('Все компании'!$W$5:$W$53,MATCH(C14,'Все компании'!$B$5:$B$53,0)),"") -> B | I14: Не связывались
A15: AT13-2 | B15: 4 | C15: Smart Heating Systems | D15: ОВиК-инжиниринг, сервис | E15: =IFERROR(INDEX('Все компании'!$Q$5:$Q$53,MATCH(C15,'Все компании'!$B$5:$B$53,0)),"") -> +998 71 248 79 79; +998 90 926 67 76; +998 97 480 79 80 | F15: =IFERROR(INDEX('Все компании'!$R$5:$R$53,MATCH(C15,'Все компании'!$B$5:$B$53,0)),"") -> info@smartheating.uz | G15: =IFERROR(INDEX('Все компании'!$S$5:$S$53,MATCH(C15,'Все компании'!$B$5:$B$53,0)),"") -> smartheating.uz | H15: =IFERROR(INDEX('Все компании'!$W$5:$W$53,MATCH(C15,'Все компании'!$B$5:$B$53,0)),"") -> A | I15: Не связывались
A16: AT13-2 | B16: 5 | C16: Climate Center | D16: Ремонт промышленных чиллеров разных марок | E16: =IFERROR(INDEX('Все компании'!$Q$5:$Q$53,MATCH(C16,'Все компании'!$B$5:$B$53,0)),"") -> +998 90 849 22 22 (также Telegram) | F16: =IFERROR(INDEX('Все компании'!$R$5:$R$53,MATCH(C16,'Все компании'!$B$5:$B$53,0)),"") -> — | G16: =IFERROR(INDEX('Все компании'!$S$5:$S$53,MATCH(C16,'Все компании'!$B$5:$B$53,0)),"") -> climatecenter.uz | H16: =IFERROR(INDEX('Все компании'!$W$5:$W$53,MATCH(C16,'Все компании'!$B$5:$B$53,0)),"") -> B | I16: Не связывались
A17: AT13 Лот 3. Газ и котельная (3×Italheat 1,6 МВт, ГРП)
A18: AT13-3 | B18: 1 | C18: ITALHEAT GROUP (СП ООО) | D18: Поставщик котлов Italheat, установленных на объекте | E18: =IFERROR(INDEX('Все компании'!$Q$5:$Q$53,MATCH(C18,'Все компании'!$B$5:$B$53,0)),"") -> +998 71 231 64 99; +998 71 231 64 90 | F18: =IFERROR(INDEX('Все компании'!$R$5:$R$53,MATCH(C18,'Все компании'!$B$5:$B$53,0)),"") -> info@italheat.com | G18: =IFERROR(INDEX('Все компании'!$S$5:$S$53,MATCH(C18,'Все компании'!$B$5:$B$53,0)),"") -> italheat.com | H18: =IFERROR(INDEX('Все компании'!$W$5:$W$53,MATCH(C18,'Все компании'!$B$5:$B$53,0)),"") -> B | I18: Не связывались
A19: AT13-3 | B19: 2 | C19: FUSE HVAC Engineering | D19: ТО котельных, подготовка к отопительному сезону | E19: =IFERROR(INDEX('Все компании'!$Q$5:$Q$53,MATCH(C19,'Все компании'!$B$5:$B$53,0)),"") -> +998 90 998 00 50 (также Telegram) | F19: =IFERROR(INDEX('Все компании'!$R$5:$R$53,MATCH(C19,'Все компании'!$B$5:$B$53,0)),"") -> info@fuse.uz | G19: =IFERROR(INDEX('Все компании'!$S$5:$S$53,MATCH(C19,'Все компании'!$B$5:$B$53,0)),"") -> fuse.uz | H19: =IFERROR(INDEX('Все компании'!$W$5:$W$53,MATCH(C19,'Все компании'!$B$5:$B$53,0)),"") -> A | I19: Не связывались
A20: AT13-3 | B20: 3 | C20: Smart Heating Systems | D20: Котлы, насосы, теплообменники | E20: =IFERROR(INDEX('Все компании'!$Q$5:$Q$53,MATCH(C20,'Все компании'!$B$5:$B$53,0)),"") -> +998 71 248 79 79; +998 90 926 67 76; +998 97 480 79 80 | F20: =IFERROR(INDEX('Все компании'!$R$5:$R$53,MATCH(C20,'Все компании'!$B$5:$B$53,0)),"") -> info@smartheating.uz | G20: =IFERROR(INDEX('Все компании'!$S$5:$S$53,MATCH(C20,'Все компании'!$B$5:$B$53,0)),"") -> smartheating.uz | H20: =IFERROR(INDEX('Все компании'!$W$5:$W$53,MATCH(C20,'Все компании'!$B$5:$B$53,0)),"") -> A | I20: Не связывались
A21: AT13-3 | B21: 4 | C21: Gas Service | D21: Эксплуатация ГРП/ГРПШ — субподряд по ГРП | E21: =IFERROR(INDEX('Все компании'!$Q$5:$Q$53,MATCH(C21,'Все компании'!$B$5:$B$53,0)),"") -> — | F21: =IFERROR(INDEX('Все компании'!$R$5:$R$53,MATCH(C21,'Все компании'!$B$5:$B$53,0)),"") -> — | G21: =IFERROR(INDEX('Все компании'!$S$5:$S$53,MATCH(C21,'Все компании'!$B$5:$B$53,0)),"") -> — | H21: =IFERROR(INDEX('Все компании'!$W$5:$W$53,MATCH(C21,'Все компании'!$B$5:$B$53,0)),"") -> C | I21: Не связывались
A22: AT13-3 | B22: 5 | C22: BTS Group | D22: Сервис промышленных горелок — субподряд | E22: =IFERROR(INDEX('Все компании'!$Q$5:$Q$53,MATCH(C22,'Все компании'!$B$5:$B$53,0)),"") -> — | F22: =IFERROR(INDEX('Все компании'!$R$5:$R$53,MATCH(C22,'Все компании'!$B$5:$B$53,0)),"") -> — | G22: =IFERROR(INDEX('Все компании'!$S$5:$S$53,MATCH(C22,'Все компании'!$B$5:$B$53,0)),"") -> btsgroup.uz | H22: =IFERROR(INDEX('Все компании'!$W$5:$W$53,MATCH(C22,'Все компании'!$B$5:$B$53,0)),"") -> C | I22: Не связывались
A23: AT13 Лот 4. Лифты (4 шт.)
A24: AT13-4 | B24: 1 | C24: Lift Universal (ООО «LIFT-UNIVERSAL») | D24: Если лифты KONE — официальный партнёр | E24: =IFERROR(INDEX('Все компании'!$Q$5:$Q$53,MATCH(C24,'Все компании'!$B$5:$B$53,0)),"") -> +998 71 205 52 25; +998 71 254 86 06 | F24: =IFERROR(INDEX('Все компании'!$R$5:$R$53,MATCH(C24,'Все компании'!$B$5:$B$53,0)),"") -> info@lift-universal.uz | G24: =IFERROR(INDEX('Все компании'!$S$5:$S$53,MATCH(C24,'Все компании'!$B$5:$B$53,0)),"") -> lift-universal.uz | H24: =IFERROR(INDEX('Все компании'!$W$5:$W$53,MATCH(C24,'Все компании'!$B$5:$B$53,0)),"") -> A | I24: Не связывались
A25: AT13-4 | B25: 2 | C25: LIFTEES (Expert Elevator System) | D25: Если лифты Otis — официальный дистрибьютор | E25: =IFERROR(INDEX('Все компании'!$Q$5:$Q$53,MATCH(C25,'Все компании'!$B$5:$B$53,0)),"") -> +998 71 207 40 04 | F25: =IFERROR(INDEX('Все компании'!$R$5:$R$53,MATCH(C25,'Все компании'!$B$5:$B$53,0)),"") -> info@liftees.uz; tahir.salihov@mail.ru (Expert Elevator Service) | G25: =IFERROR(INDEX('Все компании'!$S$5:$S$53,MATCH(C25,'Все компании'!$B$5:$B$53,0)),"") -> liftees.uz | H25: =IFERROR(INDEX('Все компании'!$W$5:$W$53,MATCH(C25,'Все компании'!$B$5:$B$53,0)),"") -> A | I25: Не связывались
A26: AT13-4 | B26: 3 | C26: VALT LIFT (ООО «VALT-LIFT») | D26: В реестре разрешений; ТО лифтов любых марок | E26: =IFERROR(INDEX('Все компании'!$Q$5:$Q$53,MATCH(C26,'Все компании'!$B$5:$B$53,0)),"") -> +998 71 235 20 05 | F26: =IFERROR(INDEX('Все компании'!$R$5:$R$53,MATCH(C26,'Все компании'!$B$5:$B$53,0)),"") -> info@valtlift.com | G26: =IFERROR(INDEX('Все компании'!$S$5:$S$53,MATCH(C26,'Все компании'!$B$5:$B$53,0)),"") -> valtlift.com | H26: =IFERROR(INDEX('Все компании'!$W$5:$W$53,MATCH(C26,'Все компании'!$B$5:$B$53,0)),"") -> A | I26: Не связывались
A27: AT13-4 | B27: 4 | C27: Master-Lift (ООО «MASTER-LIFT») | D27: В реестре разрешений | E27: =IFERROR(INDEX('Все компании'!$Q$5:$Q$53,MATCH(C27,'Все компании'!$B$5:$B$53,0)),"") -> +998 94 660 41 52; +998 95 169 74 63; +998 95 143 74 63 | F27: =IFERROR(INDEX('Все компании'!$R$5:$R$53,MATCH(C27,'Все компании'!$B$5:$B$53,0)),"") -> masterlift@list.ru | G27: =IFERROR(INDEX('Все компании'!$S$5:$S$53,MATCH(C27,'Все компании'!$B$5:$B$53,0)),"") -> — | H27: =IFERROR(INDEX('Все компании'!$W$5:$W$53,MATCH(C27,'Все компании'!$B$5:$B$53,0)),"") -> B | I27: Не связывались
A28: AT13-4 | B28: 5 | C28: High Lift Solution | D28: В реестре разрешений | E28: =IFERROR(INDEX('Все компании'!$Q$5:$Q$53,MATCH(C28,'Все компании'!$B$5:$B$53,0)),"") -> +998 33 038 88 88 | F28: =IFERROR(INDEX('Все компании'!$R$5:$R$53,MATCH(C28,'Все компании'!$B$5:$B$53,0)),"") -> — | G28: =IFERROR(INDEX('Все компании'!$S$5:$S$53,MATCH(C28,'Все компании'!$B$5:$B$53,0)),"") -> high-lift.uz | H28: =IFERROR(INDEX('Все компании'!$W$5:$W$53,MATCH(C28,'Все компании'!$B$5:$B$53,0)),"") -> B | I28: Не связывались
A29: AT13 Лот 5. Сантехника и тепловые пункты (пост 24/7)
A30: AT13-5 | B30: 1 | C30: Smart Heating Systems | D30: Теплообменники, циркуляционные насосы (ИТП/ТП) | E30: =IFERROR(INDEX('Все компании'!$Q$5:$Q$53,MATCH(C30,'Все компании'!$B$5:$B$53,0)),"") -> +998 71 248 79 79; +998 90 926 67 76; +998 97 480 79 80 | F30: =IFERROR(INDEX('Все компании'!$R$5:$R$53,MATCH(C30,'Все компании'!$B$5:$B$53,0)),"") -> info@smartheating.uz | G30: =IFERROR(INDEX('Все компании'!$S$5:$S$53,MATCH(C30,'Все компании'!$B$5:$B$53,0)),"") -> smartheating.uz | H30: =IFERROR(INDEX('Все компании'!$W$5:$W$53,MATCH(C30,'Все компании'!$B$5:$B$53,0)),"") -> A | I30: Не связывались
A31: AT13-5 | B31: 2 | C31: Reshenie.uz | D31: Водоснабжение, канализация, отопление в составе техэксплуатации | E31: =IFERROR(INDEX('Все компании'!$Q$5:$Q$53,MATCH(C31,'Все компании'!$B$5:$B$53,0)),"") -> +998 93 103 70 77 (Telegram/WhatsApp) | F31: =IFERROR(INDEX('Все компании'!$R$5:$R$53,MATCH(C31,'Все компании'!$B$5:$B$53,0)),"") -> reshenie.uz@mail.ru (на англ. версии — ssaash@mail.ru) | G31: =IFERROR(INDEX('Все компании'!$S$5:$S$53,MATCH(C31,'Все компании'!$B$5:$B$53,0)),"") -> reshenie.uz | H31: =IFERROR(INDEX('Все компании'!$W$5:$W$53,MATCH(C31,'Все компании'!$B$5:$B$53,0)),"") -> B | I31: Не связывались
A32: AT13-5 | B32: 3 | C32: FUSE HVAC Engineering | D32: Промывка систем отопления, насосы | E32: =IFERROR(INDEX('Все компании'!$Q$5:$Q$53,MATCH(C32,'Все компании'!$B$5:$B$53,0)),"") -> +998 90 998 00 50 (также Telegram) | F32: =IFERROR(INDEX('Все компании'!$R$5:$R$53,MATCH(C32,'Все компании'!$B$5:$B$53,0)),"") -> info@fuse.uz | G32: =IFERROR(INDEX('Все компании'!$S$5:$S$53,MATCH(C32,'Все компании'!$B$5:$B$53,0)),"") -> fuse.uz | H32: =IFERROR(INDEX('Все компании'!$W$5:$W$53,MATCH(C32,'Все компании'!$B$5:$B$53,0)),"") -> A | I32: Не связывались
A33: AT13-5 | B33: 4 | C33: EUROSANT | D33: Абонентская сантехника для организаций | E33: =IFERROR(INDEX('Все компании'!$Q$5:$Q$53,MATCH(C33,'Все компании'!$B$5:$B$53,0)),"") -> — | F33: =IFERROR(INDEX('Все компании'!$R$5:$R$53,MATCH(C33,'Все компании'!$B$5:$B$53,0)),"") -> — | G33: =IFERROR(INDEX('Все компании'!$S$5:$S$53,MATCH(C33,'Все компании'!$B$5:$B$53,0)),"") -> eurosant.uz | H33: =IFERROR(INDEX('Все компании'!$W$5:$W$53,MATCH(C33,'Все компании'!$B$5:$B$53,0)),"") -> C | I33: Не связывались
A34: AT13 Лот 6. Благоустройство: покрытия, газоны, фонтаны, плотник, фасад
A35: AT13-6 | B35: 1 | C35: NewCleaner | D35: Уборка территории + озеленение коммерческих объектов | E35: =IFERROR(INDEX('Все компании'!$Q$5:$Q$53,MATCH(C35,'Все компании'!$B$5:$B$53,0)),"") -> +998 94 431 62 22; +998 33 100 22 00 | F35: =IFERROR(INDEX('Все компании'!$R$5:$R$53,MATCH(C35,'Все компании'!$B$5:$B$53,0)),"") -> info@newcleaner.uz | G35: =IFERROR(INDEX('Все компании'!$S$5:$S$53,MATCH(C35,'Все компании'!$B$5:$B$53,0)),"") -> newcleaner.uz | H35: =IFERROR(INDEX('Все компании'!$W$5:$W$53,MATCH(C35,'Все компании'!$B$5:$B$53,0)),"") -> A | I35: Не связывались
A36: AT13-6 | B36: 2 | C36: ProGazon | D36: Газоны и обслуживание участков | E36: =IFERROR(INDEX('Все компании'!$Q$5:$Q$53,MATCH(C36,'Все компании'!$B$5:$B$53,0)),"") -> +998 97 712 88 89; +998 90 915 55 56 | F36: =IFERROR(INDEX('Все компании'!$R$5:$R$53,MATCH(C36,'Все компании'!$B$5:$B$53,0)),"") -> info@progazon.uz | G36: =IFERROR(INDEX('Все компании'!$S$5:$S$53,MATCH(C36,'Все компании'!$B$5:$B$53,0)),"") -> progazon.uz | H36: =IFERROR(INDEX('Все компании'!$W$5:$W$53,MATCH(C36,'Все компании'!$B$5:$B$53,0)),"") -> B | I36: Не связывались
A37: AT13-6 | B37: 3 | C37: Gazon Markazi (Ташкентский Газонный Центр) | D37: Стрижка и уход за газонами | E37: =IFERROR(INDEX('Все компании'!$Q$5:$Q$53,MATCH(C37,'Все компании'!$B$5:$B$53,0)),"") -> +998 90 175 47 20 | F37: =IFERROR(INDEX('Все компании'!$R$5:$R$53,MATCH(C37,'Все компании'!$B$5:$B$53,0)),"") -> — | G37: =IFERROR(INDEX('Все компании'!$S$5:$S$53,MATCH(C37,'Все компании'!$B$5:$B$53,0)),"") -> — | H37: =IFERROR(INDEX('Все компании'!$W$5:$W$53,MATCH(C37,'Все компании'!$B$5:$B$53,0)),"") -> C | I37: Не связывались
A38: AT13-6 | B38: 4 | C38: Sky Clean | D38: Фасады и высотные работы (мойка фасада — субподряд) | E38: =IFERROR(INDEX('Все компании'!$Q$5:$Q$53,MATCH(C38,'Все компании'!$B$5:$B$53,0)),"") -> +998 99 099 99 83 | F38: =IFERROR(INDEX('Все компании'!$R$5:$R$53,MATCH(C38,'Все компании'!$B$5:$B$53,0)),"") -> info@skyclean.uz | G38: =IFERROR(INDEX('Все компании'!$S$5:$S$53,MATCH(C38,'Все компании'!$B$5:$B$53,0)),"") -> skyclean.uz | H38: =IFERROR(INDEX('Все компании'!$W$5:$W$53,MATCH(C38,'Все компании'!$B$5:$B$53,0)),"") -> A | I38: Не связывались
A39: AT13-6 | B39: 5 | C39: Cleaning Service Tashkent (ООО) | D39: Мойка фасадов, обслуживание территорий | E39: =IFERROR(INDEX('Все компании'!$Q$5:$Q$53,MATCH(C39,'Все компании'!$B$5:$B$53,0)),"") -> 90 995 00 44 (номер в каталоге неполный, проверить) | F39: =IFERROR(INDEX('Все компании'!$R$5:$R$53,MATCH(C39,'Все компании'!$B$5:$B$53,0)),"") -> cstashkent@mail.ru | G39: =IFERROR(INDEX('Все компании'!$S$5:$S$53,MATCH(C39,'Все компании'!$B$5:$B$53,0)),"") -> cleaning.uz | H39: =IFERROR(INDEX('Все компании'!$W$5:$W$53,MATCH(C39,'Все компании'!$B$5:$B$53,0)),"") -> B | I39: Не связывались

Sheet MU30 тех шорт-лист
A1: MU30 тех шорт-лист: приоритетные компании для запроса КП
A2: Контакты подтягиваются формулами из листа «Все компании». Жёлтые колонки — для отметок закупщика (статус — из списка).
A4: Лот | B4: Приоритет | C4: Компания | D4: Почему в списке | E4: Телефон(ы) | F4: E-mail | G4: Сайт | H4: Достоверность | I4: Статус | J4: Дата запроса | K4: Комментарий
A5: MU30 тех. Лот 1. Электроснабжение (дневной пост)
A6: MU30T-1 | B6: 1 | C6: Reshenie.uz | D6: Техэксплуатация зданий | E6: =IFERROR(INDEX('Все компании'!$Q$5:$Q$53,MATCH(C6,'Все компании'!$B$5:$B$53,0)),"") -> +998 93 103 70 77 (Telegram/WhatsApp) | F6: =IFERROR(INDEX('Все компании'!$R$5:$R$53,MATCH(C6,'Все компании'!$B$5:$B$53,0)),"") -> reshenie.uz@mail.ru (на англ. версии — ssaash@mail.ru) | G6: =IFERROR(INDEX('Все компании'!$S$5:$S$53,MATCH(C6,'Все компании'!$B$5:$B$53,0)),"") -> reshenie.uz | H6: =IFERROR(INDEX('Все компании'!$W$5:$W$53,MATCH(C6,'Все компании'!$B$5:$B$53,0)),"") -> B | I6: Не связывались
A7: MU30T-1 | B7: 2 | C7: Eco-Service (service-eco.uz) | D7: Электрики | E7: =IFERROR(INDEX('Все компании'!$Q$5:$Q$53,MATCH(C7,'Все компании'!$B$5:$B$53,0)),"") -> +998 78 555 48 94; +998 88 113 87 87 | F7: =IFERROR(INDEX('Все компании'!$R$5:$R$53,MATCH(C7,'Все компании'!$B$5:$B$53,0)),"") -> — | G7: =IFERROR(INDEX('Все компании'!$S$5:$S$53,MATCH(C7,'Все компании'!$B$5:$B$53,0)),"") -> service-eco.uz | H7: =IFERROR(INDEX('Все компании'!$W$5:$W$53,MATCH(C7,'Все компании'!$B$5:$B$53,0)),"") -> B | I7: Не связывались
A8: MU30T-1 | B8: 3 | C8: SVET.UZ (OMEGA ENGINEERING GROUP) | D8: Электромонтаж | E8: =IFERROR(INDEX('Все компании'!$Q$5:$Q$53,MATCH(C8,'Все компании'!$B$5:$B$53,0)),"") -> +998 99 855 18 55; +998 99 825 82 56 | F8: =IFERROR(INDEX('Все компании'!$R$5:$R$53,MATCH(C8,'Все компании'!$B$5:$B$53,0)),"") -> — | G8: =IFERROR(INDEX('Все компании'!$S$5:$S$53,MATCH(C8,'Все компании'!$B$5:$B$53,0)),"") -> svet.uz | H8: =IFERROR(INDEX('Все компании'!$W$5:$W$53,MATCH(C8,'Все компании'!$B$5:$B$53,0)),"") -> B | I8: Не связывались
A9: MU30T-1 | B9: 4 | C9: PROF-LEND (ООО) | D9: Электролаборатория (замеры, поверка) | E9: =IFERROR(INDEX('Все компании'!$Q$5:$Q$53,MATCH(C9,'Все компании'!$B$5:$B$53,0)),"") -> +998 90 187 14 67 | F9: =IFERROR(INDEX('Все компании'!$R$5:$R$53,MATCH(C9,'Все компании'!$B$5:$B$53,0)),"") -> admin@proflend.uz | G9: =IFERROR(INDEX('Все компании'!$S$5:$S$53,MATCH(C9,'Все компании'!$B$5:$B$53,0)),"") -> proflend.uz | H9: =IFERROR(INDEX('Все компании'!$W$5:$W$53,MATCH(C9,'Все компании'!$B$5:$B$53,0)),"") -> A | I9: Не связывались
A10: MU30 тех. Лот 2. Сантехника (дневной пост)
A11: MU30T-2 | B11: 1 | C11: Reshenie.uz | D11: Техэксплуатация зданий | E11: =IFERROR(INDEX('Все компании'!$Q$5:$Q$53,MATCH(C11,'Все компании'!$B$5:$B$53,0)),"") -> +998 93 103 70 77 (Telegram/WhatsApp) | F11: =IFERROR(INDEX('Все компании'!$R$5:$R$53,MATCH(C11,'Все компании'!$B$5:$B$53,0)),"") -> reshenie.uz@mail.ru (на англ. версии — ssaash@mail.ru) | G11: =IFERROR(INDEX('Все компании'!$S$5:$S$53,MATCH(C11,'Все компании'!$B$5:$B$53,0)),"") -> reshenie.uz | H11: =IFERROR(INDEX('Все компании'!$W$5:$W$53,MATCH(C11,'Все компании'!$B$5:$B$53,0)),"") -> B | I11: Не связывались
A12: MU30T-2 | B12: 2 | C12: Eco-Service (service-eco.uz) | D12: Многопрофильный сервис | E12: =IFERROR(INDEX('Все компании'!$Q$5:$Q$53,MATCH(C12,'Все компании'!$B$5:$B$53,0)),"") -> +998 78 555 48 94; +998 88 113 87 87 | F12: =IFERROR(INDEX('Все компании'!$R$5:$R$53,MATCH(C12,'Все компании'!$B$5:$B$53,0)),"") -> — | G12: =IFERROR(INDEX('Все компании'!$S$5:$S$53,MATCH(C12,'Все компании'!$B$5:$B$53,0)),"") -> service-eco.uz | H12: =IFERROR(INDEX('Все компании'!$W$5:$W$53,MATCH(C12,'Все компании'!$B$5:$B$53,0)),"") -> B | I12: Не связывались
A13: MU30T-2 | B13: 3 | C13: EUROSANT | D13: Абонентская сантехника | E13: =IFERROR(INDEX('Все компании'!$Q$5:$Q$53,MATCH(C13,'Все компании'!$B$5:$B$53,0)),"") -> — | F13: =IFERROR(INDEX('Все компании'!$R$5:$R$53,MATCH(C13,'Все компании'!$B$5:$B$53,0)),"") -> — | G13: =IFERROR(INDEX('Все компании'!$S$5:$S$53,MATCH(C13,'Все компании'!$B$5:$B$53,0)),"") -> eurosant.uz | H13: =IFERROR(INDEX('Все компании'!$W$5:$W$53,MATCH(C13,'Все компании'!$B$5:$B$53,0)),"") -> C | I13: Не связывались
A14: MU30T-2 | B14: 4 | C14: Smart Heating Systems | D14: Водо- и теплоснабжение | E14: =IFERROR(INDEX('Все компании'!$Q$5:$Q$53,MATCH(C14,'Все компании'!$B$5:$B$53,0)),"") -> +998 71 248 79 79; +998 90 926 67 76; +998 97 480 79 80 | F14: =IFERROR(INDEX('Все компании'!$R$5:$R$53,MATCH(C14,'Все компании'!$B$5:$B$53,0)),"") -> info@smartheating.uz | G14: =IFERROR(INDEX('Все компании'!$S$5:$S$53,MATCH(C14,'Все компании'!$B$5:$B$53,0)),"") -> smartheating.uz | H14: =IFERROR(INDEX('Все компании'!$W$5:$W$53,MATCH(C14,'Все компании'!$B$5:$B$53,0)),"") -> A | I14: Не связывались
A15: MU30 тех. Лот 3. Лифт (1 шт.)
A16: MU30T-3 | B16: 1 | C16: VALT LIFT (ООО «VALT-LIFT») | D16: В реестре разрешений | E16: =IFERROR(INDEX('Все компании'!$Q$5:$Q$53,MATCH(C16,'Все компании'!$B$5:$B$53,0)),"") -> +998 71 235 20 05 | F16: =IFERROR(INDEX('Все компании'!$R$5:$R$53,MATCH(C16,'Все компании'!$B$5:$B$53,0)),"") -> info@valtlift.com | G16: =IFERROR(INDEX('Все компании'!$S$5:$S$53,MATCH(C16,'Все компании'!$B$5:$B$53,0)),"") -> valtlift.com | H16: =IFERROR(INDEX('Все компании'!$W$5:$W$53,MATCH(C16,'Все компании'!$B$5:$B$53,0)),"") -> A | I16: Не связывались
A17: MU30T-3 | B17: 2 | C17: Lift Universal (ООО «LIFT-UNIVERSAL») | D17: Если лифт KONE | E17: =IFERROR(INDEX('Все компании'!$Q$5:$Q$53,MATCH(C17,'Все компании'!$B$5:$B$53,0)),"") -> +998 71 205 52 25; +998 71 254 86 06 | F17: =IFERROR(INDEX('Все компании'!$R$5:$R$53,MATCH(C17,'Все компании'!$B$5:$B$53,0)),"") -> info@lift-universal.uz | G17: =IFERROR(INDEX('Все компании'!$S$5:$S$53,MATCH(C17,'Все компании'!$B$5:$B$53,0)),"") -> lift-universal.uz | H17: =IFERROR(INDEX('Все компании'!$W$5:$W$53,MATCH(C17,'Все компании'!$B$5:$B$53,0)),"") -> A | I17: Не связывались
A18: MU30T-3 | B18: 3 | C18: Master-Lift (ООО «MASTER-LIFT») | D18: В реестре разрешений | E18: =IFERROR(INDEX('Все компании'!$Q$5:$Q$53,MATCH(C18,'Все компании'!$B$5:$B$53,0)),"") -> +998 94 660 41 52; +998 95 169 74 63; +998 95 143 74 63 | F18: =IFERROR(INDEX('Все компании'!$R$5:$R$53,MATCH(C18,'Все компании'!$B$5:$B$53,0)),"") -> masterlift@list.ru | G18: =IFERROR(INDEX('Все компании'!$S$5:$S$53,MATCH(C18,'Все компании'!$B$5:$B$53,0)),"") -> — | H18: =IFERROR(INDEX('Все компании'!$W$5:$W$53,MATCH(C18,'Все компании'!$B$5:$B$53,0)),"") -> B | I18: Не связывались
A19: MU30T-3 | B19: 4 | C19: LIFTEES (Expert Elevator System) | D19: Если лифт Otis | E19: =IFERROR(INDEX('Все компании'!$Q$5:$Q$53,MATCH(C19,'Все компании'!$B$5:$B$53,0)),"") -> +998 71 207 40 04 | F19: =IFERROR(INDEX('Все компании'!$R$5:$R$53,MATCH(C19,'Все компании'!$B$5:$B$53,0)),"") -> info@liftees.uz; tahir.salihov@mail.ru (Expert Elevator Service) | G19: =IFERROR(INDEX('Все компании'!$S$5:$S$53,MATCH(C19,'Все компании'!$B$5:$B$53,0)),"") -> liftees.uz | H19: =IFERROR(INDEX('Все компании'!$W$5:$W$53,MATCH(C19,'Все компании'!$B$5:$B$53,0)),"") -> A | I19: Не связывались
A20: MU30T-3 | B20: 5 | C20: Beta Lift Asia Uzbekistan | D20: В реестре разрешений | E20: =IFERROR(INDEX('Все компании'!$Q$5:$Q$53,MATCH(C20,'Все компании'!$B$5:$B$53,0)),"") -> +998 90 043 40 30; +998 90 047 40 30; +998 78 147 40 30 | F20: =IFERROR(INDEX('Все компании'!$R$5:$R$53,MATCH(C20,'Все компании'!$B$5:$B$53,0)),"") -> — | G20: =IFERROR(INDEX('Все компании'!$S$5:$S$53,MATCH(C20,'Все компании'!$B$5:$B$53,0)),"") -> — | H20: =IFERROR(INDEX('Все компании'!$W$5:$W$53,MATCH(C20,'Все компании'!$B$5:$B$53,0)),"") -> B | I20: Не связывались
A21: MU30 тех. Лот 4. Территория и газоны
A22: MU30T-4 | B22: 1 | C22: NewCleaner | D22: Территория + озеленение; можно объединить с клинингом | E22: =IFERROR(INDEX('Все компании'!$Q$5:$Q$53,MATCH(C22,'Все компании'!$B$5:$B$53,0)),"") -> +998 94 431 62 22; +998 33 100 22 00 | F22: =IFERROR(INDEX('Все компании'!$R$5:$R$53,MATCH(C22,'Все компании'!$B$5:$B$53,0)),"") -> info@newcleaner.uz | G22: =IFERROR(INDEX('Все компании'!$S$5:$S$53,MATCH(C22,'Все компании'!$B$5:$B$53,0)),"") -> newcleaner.uz | H22: =IFERROR(INDEX('Все компании'!$W$5:$W$53,MATCH(C22,'Все компании'!$B$5:$B$53,0)),"") -> A | I22: Не связывались
A23: MU30T-4 | B23: 2 | C23: ProGazon | D23: Газоны | E23: =IFERROR(INDEX('Все компании'!$Q$5:$Q$53,MATCH(C23,'Все компании'!$B$5:$B$53,0)),"") -> +998 97 712 88 89; +998 90 915 55 56 | F23: =IFERROR(INDEX('Все компании'!$R$5:$R$53,MATCH(C23,'Все компании'!$B$5:$B$53,0)),"") -> info@progazon.uz | G23: =IFERROR(INDEX('Все компании'!$S$5:$S$53,MATCH(C23,'Все компании'!$B$5:$B$53,0)),"") -> progazon.uz | H23: =IFERROR(INDEX('Все компании'!$W$5:$W$53,MATCH(C23,'Все компании'!$B$5:$B$53,0)),"") -> B | I23: Не связывались
A24: MU30T-4 | B24: 3 | C24: Gazon Markazi (Ташкентский Газонный Центр) | D24: Уход за газонами | E24: =IFERROR(INDEX('Все компании'!$Q$5:$Q$53,MATCH(C24,'Все компании'!$B$5:$B$53,0)),"") -> +998 90 175 47 20 | F24: =IFERROR(INDEX('Все компании'!$R$5:$R$53,MATCH(C24,'Все компании'!$B$5:$B$53,0)),"") -> — | G24: =IFERROR(INDEX('Все компании'!$S$5:$S$53,MATCH(C24,'Все компании'!$B$5:$B$53,0)),"") -> — | H24: =IFERROR(INDEX('Все компании'!$W$5:$W$53,MATCH(C24,'Все компании'!$B$5:$B$53,0)),"") -> C | I24: Не связывались
A25: MU30T-4 | B25: 4 | C25: Cleaning Service Tashkent (ООО) | D25: Обслуживание территорий | E25: =IFERROR(INDEX('Все компании'!$Q$5:$Q$53,MATCH(C25,'Все компании'!$B$5:$B$53,0)),"") -> 90 995 00 44 (номер в каталоге неполный, проверить) | F25: =IFERROR(INDEX('Все компании'!$R$5:$R$53,MATCH(C25,'Все компании'!$B$5:$B$53,0)),"") -> cstashkent@mail.ru | G25: =IFERROR(INDEX('Все компании'!$S$5:$S$53,MATCH(C25,'Все компании'!$B$5:$B$53,0)),"") -> cleaning.uz | H25: =IFERROR(INDEX('Все компании'!$W$5:$W$53,MATCH(C25,'Все компании'!$B$5:$B$53,0)),"") -> B | I25: Не связывались

Sheet MU30 клининг шорт-лист
A1: MU30 клининг шорт-лист: приоритетные компании для запроса КП
A2: Контакты подтягиваются формулами из листа «Все компании». Жёлтые колонки — для отметок закупщика (статус — из списка).
A4: Лот | B4: Приоритет | C4: Компания | D4: Почему в списке | E4: Телефон(ы) | F4: E-mail | G4: Сайт | H4: Достоверность | I4: Статус | J4: Дата запроса | K4: Комментарий
A5: MU30 клининг. Уборка МОП 2 305,19 м²
A6: MU30K | B6: 1 | C6: Profuborka (Asia Cleaning Service) | D6: ~100 сотрудников, ежедневная уборка офисов для юрлиц | E6: =IFERROR(INDEX('Все компании'!$Q$5:$Q$53,MATCH(C6,'Все компании'!$B$5:$B$53,0)),"") -> +998 71 200 03 28; +998 97 402 28 20; +998 97 037 28 20 | F6: =IFERROR(INDEX('Все компании'!$R$5:$R$53,MATCH(C6,'Все компании'!$B$5:$B$53,0)),"") -> asiaclean@mail.ru | G6: =IFERROR(INDEX('Все компании'!$S$5:$S$53,MATCH(C6,'Все компании'!$B$5:$B$53,0)),"") -> profuborka.uz | H6: =IFERROR(INDEX('Все компании'!$W$5:$W$53,MATCH(C6,'Все компании'!$B$5:$B$53,0)),"") -> A | I6: Не связывались
A7: MU30K | B7: 2 | C7: NewCleaner | D7: Офисы и коммерческие объекты; может взять и территорию | E7: =IFERROR(INDEX('Все компании'!$Q$5:$Q$53,MATCH(C7,'Все компании'!$B$5:$B$53,0)),"") -> +998 94 431 62 22; +998 33 100 22 00 | F7: =IFERROR(INDEX('Все компании'!$R$5:$R$53,MATCH(C7,'Все компании'!$B$5:$B$53,0)),"") -> info@newcleaner.uz | G7: =IFERROR(INDEX('Все компании'!$S$5:$S$53,MATCH(C7,'Все компании'!$B$5:$B$53,0)),"") -> newcleaner.uz | H7: =IFERROR(INDEX('Все компании'!$W$5:$W$53,MATCH(C7,'Все компании'!$B$5:$B$53,0)),"") -> A | I7: Не связывались
A8: MU30K | B8: 3 | C8: Uborka24 | D8: Общие зоны бизнес-центров | E8: =IFERROR(INDEX('Все компании'!$Q$5:$Q$53,MATCH(C8,'Все компании'!$B$5:$B$53,0)),"") -> +998 94 880 95 45 (заказ); +998 33 979 67 68 (жалобы) | F8: =IFERROR(INDEX('Все компании'!$R$5:$R$53,MATCH(C8,'Все компании'!$B$5:$B$53,0)),"") -> info@uborka24.uz | G8: =IFERROR(INDEX('Все компании'!$S$5:$S$53,MATCH(C8,'Все компании'!$B$5:$B$53,0)),"") -> uborka24.uz | H8: =IFERROR(INDEX('Все компании'!$W$5:$W$53,MATCH(C8,'Все компании'!$B$5:$B$53,0)),"") -> A | I8: Не связывались
A9: MU30K | B9: 4 | C9: Sky Clean | D9: Только юрлица; высотные работы для генуборки | E9: =IFERROR(INDEX('Все компании'!$Q$5:$Q$53,MATCH(C9,'Все компании'!$B$5:$B$53,0)),"") -> +998 99 099 99 83 | F9: =IFERROR(INDEX('Все компании'!$R$5:$R$53,MATCH(C9,'Все компании'!$B$5:$B$53,0)),"") -> info@skyclean.uz | G9: =IFERROR(INDEX('Все компании'!$S$5:$S$53,MATCH(C9,'Все компании'!$B$5:$B$53,0)),"") -> skyclean.uz | H9: =IFERROR(INDEX('Все компании'!$W$5:$W$53,MATCH(C9,'Все компании'!$B$5:$B$53,0)),"") -> A | I9: Не связывались
A10: MU30K | B10: 5 | C10: MaxHelp | D10: Офисный клининг | E10: =IFERROR(INDEX('Все компании'!$Q$5:$Q$53,MATCH(C10,'Все компании'!$B$5:$B$53,0)),"") -> +998 71 200 11 18; +998 99 229 14 55 | F10: =IFERROR(INDEX('Все компании'!$R$5:$R$53,MATCH(C10,'Все компании'!$B$5:$B$53,0)),"") -> info@maxhelp.uz | G10: =IFERROR(INDEX('Все компании'!$S$5:$S$53,MATCH(C10,'Все компании'!$B$5:$B$53,0)),"") -> maxhelp.uz | H10: =IFERROR(INDEX('Все компании'!$W$5:$W$53,MATCH(C10,'Все компании'!$B$5:$B$53,0)),"") -> B | I10: Не связывались
A11: MU30K | B11: 6 | C11: Cleaning Service Tashkent (ООО) | D11: Круглосуточная уборка офисов, окна на высоте | E11: =IFERROR(INDEX('Все компании'!$Q$5:$Q$53,MATCH(C11,'Все компании'!$B$5:$B$53,0)),"") -> 90 995 00 44 (номер в каталоге неполный, проверить) | F11: =IFERROR(INDEX('Все компании'!$R$5:$R$53,MATCH(C11,'Все компании'!$B$5:$B$53,0)),"") -> cstashkent@mail.ru | G11: =IFERROR(INDEX('Все компании'!$S$5:$S$53,MATCH(C11,'Все компании'!$B$5:$B$53,0)),"") -> cleaning.uz | H11: =IFERROR(INDEX('Все компании'!$W$5:$W$53,MATCH(C11,'Все компании'!$B$5:$B$53,0)),"") -> B | I11: Не связывались
A12: MU30K | B12: 7 | C12: Eco-Service (service-eco.uz) | D12: Договор с НДС, супервайзер на объект | E12: =IFERROR(INDEX('Все компании'!$Q$5:$Q$53,MATCH(C12,'Все компании'!$B$5:$B$53,0)),"") -> +998 78 555 48 94; +998 88 113 87 87 | F12: =IFERROR(INDEX('Все компании'!$R$5:$R$53,MATCH(C12,'Все компании'!$B$5:$B$53,0)),"") -> — | G12: =IFERROR(INDEX('Все компании'!$S$5:$S$53,MATCH(C12,'Все компании'!$B$5:$B$53,0)),"") -> service-eco.uz | H12: =IFERROR(INDEX('Все компании'!$W$5:$W$53,MATCH(C12,'Все компании'!$B$5:$B$53,0)),"") -> B | I12: Не связывались

Sheet Источники и метод
A1: Источники, метод и что проверить
A3: Метод | B3: Веб-поиск (RU/UZ/EN) по категориям: лифты, котельные и ГРП, ОВиК и чиллеры, электрика и ТП, техэксплуатация зданий, клининг, озеленение, промальпинизм. Контакты взяты из сайтов компаний и каталогов (yellowpages.uz, goldenpages.uz, top.uz, gigal.uz, prom.uz, stroyka.uz) в том виде, в каком их показал поиск.
A4: Реестр лифтовых организаций | B4: gov.uz/oz/cirns — «Sanoat, radiatsiya va yadro xavfsizligi qo‘mitasi tomonidan liftlarni montaj va ta’mirlash ishlari bilan shug‘ullanish xuquqini beruvchi ruxsatnoma olgan tashkilotlar» (видна только часть списка).
A5: В реестре КПРЯБ, контакты не найдены | B5: ELEVATOR LIFT SERVIS, LIFT TA'MIR SERVIS, FAYZ LIFT, FAYZBEK LIFT SERVIS, SHIFT LIFT, GLOBAL LIFT, EVO LIFT SERVICE, ELZA LIFT TECHNICAL CO, ARSENAL LIFT MONTAJ, LIFT EKA BARAKA, TRUST QUALITY ELEVATORS, EXPERT ELEVATOR GROUP
A6: Недоступные домены | B6: goldenpages.uz, top.uz, orginfo.uz, xarid.uzex.uz, etender.uzex.uz, 2gis.uz, olx.uz, uzorg.info, license.gov.uz, my.gov.uz, gov.uz — при сборе данных были недоступны. При доступе к ним можно дополнительно: (1) найти победителей аналогичных лотов на etender.uzex.uz / xarid.uzex.uz; (2) подтянуть ИНН и директоров с orginfo.uz; (3) сверить лицензии.
A7: Пример аналогичного лота | B7: etender.uzex.uz/lot/477402 — мойка стеклянных фасадов и витражей ~12 800 м² методом промальпинизма, пр. Амира Темура, 107Б (2026).
A8: Новое регулирование лифтов | B8: По данным UzDaily, с 2027 г. ТО лифтов не реже раза в месяц, договоры регистрируются через платформу «Xavfsiz lift» (положение, утв. постановлением № 588 от 22.10.2026). Реквизиты постановления в поиске не подтверждены — сверить на lex.uz.
A9: Что проверить при первом контакте | B9: ИНН и регистрация юрлица; плательщик НДС; лицензии и разрешения по лоту; аналогичные объекты (бизнес-центры, госкомпании); штат под посты 24/7; готовность к осмотру объекта; работа по XKD/SLA с удержаниями.
